Workbook

Sheet 表紙
AO1: 文書番号 | AP1: BMS001
G7: 社内システム構築
G9: 書籍管理システム
G11: 画面設計書
G13: 書籍一覧 (一般)
G16: ="最終更新日： "&IF(MAX(変更履歴!C5:C50)=0,"",TEXT(MAX(変更履歴!C5:C50),"YYYY/MM/DD")) -> 最終更新日： 2025/10/01
G18: マンパワーグループ株式会社

Sheet 変更履歴
A1: ■画面設計書 | AG1: 文書番号 | AJ1: =表紙!AP1 -> BMS001
A2: 画面名 | C2: =表紙!G13 -> 書籍一覧 (一般) | Q2: 縦スクロール | T2: 可 | V2: 横スクロール | Y2: 可 | AA2: 画面タイプ | AD2: 通常 | AG2: 画面URL | AJ2: /book/list
A3: ■画面概要 | AG3: ファイル名 | AJ3: book-list
A4: 版 | C4: 日付 | F4: 作成者 | J4: 変更箇所 | Q4: 修 正 内 容
A5: 0.01 | C5: 45931 | Q5: 新規作成

Sheet 画面概要
A1: ■画面設計書 | AG1: 文書番号 | AJ1: =表紙!AP1 -> BMS001
A2: 画面名 | C2: =表紙!G13 -> 書籍一覧 (一般) | Q2: 縦スクロール | T2: 可 | V2: 横スクロール | Y2: 可 | AA2: 画面タイプ | AD2: 通常 | AG2: 画面URL | AJ2: =変更履歴!AJ2 -> /book/list
A3: ■画面概要 | AG3: ファイル名 | AJ3: =変更履歴!AJ3 -> book-list
A4: 画面概要
A5: ・書籍一覧を表示できる
A6: ・書籍の在庫状況を確認できる
A7: ・書籍の詳細画面に遷移できる
A10: 機能
A11: ・書籍検索
A12: ・「貸出中」と「貸出を除く」で絞り込み
A13: ・「新着順」、「評価順」に並び替え
A14: ・詳細画面に遷移
A16: 前提条件
A17: 特になし
A20: イベント一覧
A22: イベントID | C22: イベントトリガー | G22: 処理
A23: #001 | C23: ボタン押下 | G23: 検索
A24: #002 | C24: ボタン押下 | G24: 絞り込み
A25: #003 | C25: ボタン押下 | G25: 並び替え
A29: 画面遷移先一覧
A30: ① | B30: /detail/{id}
A31: ② | B31: /menu
A33: 外部参照

Sheet 画面項目
A1: ■画面設計書 | AG1: 文書番号 | AJ1: =表紙!AP1 -> BMS001
A2: 画面名 | C2: =表紙!G13 -> 書籍一覧 (一般) | Q2: 縦スクロール | T2: 可 | V2: 横スクロール | Y2: 可 | AA2: 画面タイプ | AD2: 通常 | AG2: 画面URL | AJ2: =変更履歴!AJ2 -> /book/list
A3: ■画面項目 | AG3: ファイル名 | AJ3: =変更履歴!AJ3 -> book-list
A4: 画面イメージ
A31: 画面項目
A33: No. | C33: 項目ID | K33: 項目名(日本語) | R33: 部品種別 | V33: 必須 | X33: 初期値 | AB33: 桁数 | AD33: 備考 | AL33: イベントID
A34: 1 | C34: number_label | K34: 番号ラベル | R34: ラベル
A35: 2 | C35: number | K35: 番号 | R35: 表示項目
A36: 3 | C36: title_label | K36: 書籍名ラベル | R36: ラベル
A37: 4 | C37: title | K37: 書籍名 | R37: 表示項目 | AB37: 100
A38: 5 | C38: author_label | K38: 著者ラベル | R38: ラベル
A39: 6 | C39: author | K39: 著者 | R39: 表示項目 | AB39: 30
A40: 7 | C40: status_label | K40: 貸出状況ラベル | R40: ラベル
A41: 8 | C41: status | K41: 貸出状況 | R41: 表示項目
A42: 9 | C42: date | K42: 出版日 | R42: 非表示項目 | AD42: 並び替えのための項目
A43: 10 | C43: review | K43: 評価 | R43: 非表示項目 | AD43: 並び替えのための項目
A44: 11 | C44: keyword_input | K44: 検索欄 | R44: インプット | AD44: 「書籍名」「著者」で検索可能 | AL44: #001
A45: 12 | C45: filter_button | K45: 絞り込みドロップダウン | R45: ドロップダウン | AD45: 「貸出状況」で絞り込み可能 | AL45: #002
A46: 13 | C46: sort_button | K46: 並び替えドロップダウン | R46: ドロップダウン | AD46: 「新着順」「評価順」で並び替え可能 | AL46: #003
A47: 14 | C47: detail_button | K47: 詳細リンク | R47: リンク | AD47: 「詳細画面(/detail/{id})」へ遷移
A48: 15 | C48: menu_button | K48: メニューリンク | R48: リンク | AD48: 「メニュー画面（/menu）」へ遷移する

Sheet 画面遷移図
A1: ■画面設計書 | AG1: 文書番号 | AJ1: =表紙!AP1 -> BMS001
A2: 画面名 | C2: =表紙!G13 -> 書籍一覧 (一般) | Q2: 縦スクロール | T2: 可 | V2: 横スクロール | Y2: 可 | AA2: 画面タイプ | AD2: 通常 | AG2: 画面URL | AJ2: =変更履歴!AJ2 -> /book/list
A3: ■画面遷移図 | AG3: ファイル名 | AJ3: =変更履歴!AJ3 -> book-list
A4: 書籍一覧・予約画面遷移図

Sheet イベント定義
A1: ■画面設計書 | AG1: 文書番号 | AJ1: =表紙!AP1 -> BMS001
A2: 画面名 | C2: =表紙!G13 -> 書籍一覧 (一般) | Q2: 縦スクロール | T2: 可 | V2: 横スクロール | Y2: 可 | AA2: 画面タイプ | AD2: 通常 | AG2: 画面URL | AJ2: =変更履歴!AJ2 -> /book/list
A3: ■イベント定義 | AG3: ファイル名 | AJ3: =変更履歴!AJ3 -> book-list
A4: イベント
A6: #000 | C6: 初期表示
A8: 1 | C8: 画面に書籍一覧を表示する
A10: 1-1 | D10: データベースから書籍リストを取得する
E11: ① データベースから書籍情報を取得する（※画面項目移動表No.1を参照）
A13: 1-2 | D13: Tabulatorを設定
E14: ①Tabulatorのテーブル情報を設定する
E16: ページネーション | I16: 10件
E17: ソート | I17: 昇順
A20: 1-3 | D20: 取得した書籍情報をテーブルに描画する
E21: ① 「1-1」のデータを取得する
E22: ② 取得した書籍情報をテーブルに描画する（下記の表を参照）
E24: ヘッダー | I24: データ
E25: 番号 | I25: 「1-1」で取得した書籍のID
E26: 書籍名 | I26: 「1-1」で取得した書籍のタイトル
E27: 著者 | I27: 「1-1」で取得した書籍の著者
E28: 貸出状況 | I28: 「1-1」で取得した書籍の貸出状況
E29: 詳細予約リンク | I29: 「/detail/ + 「1-1」で取得した書籍のID」に遷移するリンク
E30: (隠し) 日付 | I30: 「1-1」で取得した書籍の日付
E31: (隠し) 評価 | I31: 「1-1」で計算した書籍の評価
A33: #001 | C33: キーワード入力
A35: 1 | C35: 検索機能
A37: 1-1 | D37: 検索欄に文字を入力する
A39: 1-2 | D39: 入力された文字から書籍一覧をあいまい検索で絞り込む
A42: #002 | C42: 絞り込み選択
A44: 1 | C44: 絞り込み機能
A46: 1-1 | D46: 絞り込みドロップダウンから絞り込み方法を選択する
A48: 1-2 | D48: 選択された方法で書籍一覧を絞り込む
D50: 選択項目 | H50: 絞り込み
H51: 全書籍を表示
D52: 貸出中 | H52: 貸出中の書籍を表示
D53: 貸出可能 | H53: 貸出されていない書籍を表示
A56: #003 | C56: 並び替え選択
A58: 1 | C58: 並び替え機能
A60: 1-1 | D60: 並び替えドロップダウンから並び替え方法を選択する
A62: 1-2 | D62: 選択された方法で書籍一覧を並び替える
D64: 選択項目 | H64: 並び替え
...

Sheet 画面項目移動表
A1: ■画面設計書 | AG1: 文書番号 | AJ1: =表紙!AP1 -> BMS001
A2: 画面名 | C2: =表紙!G13 -> 書籍一覧 (一般) | Q2: 縦スクロール | T2: 可 | V2: 横スクロール | Y2: 可 | AA2: 画面タイプ | AD2: 通常 | AG2: 画面URL | AJ2: =変更履歴!AJ2 -> /book/list
A3: ■画面項目移動表 | AG3: ファイル名 | AJ3: =変更履歴!AJ3 -> book-list
A4: 画面項目移動
A6: No.1 | C6: 取得 | E6: 初期表示データ | AA6: SQL001
A7: 番号 | C7: 取得元（テーブル名） | G7: カラム名 | K7: 反映先１（DTO名） | O7: 変数名 | S7: 反映先２（画面項目ID） | W7: 画面項目名 | AE7: 備考
A8: 1 | C8: m_book_lists | G8: id | S8: number | W8: 番号
A9: 2 | C9: m_book_lists | G9: title | S9: title | W9: 書籍名
A10: 3 | C10: m_book_lists | G10: author | S10: author | W10: 著者
A11: 4 | C11: m_book_lists | G11: publication_ date | S11: date | W11: 出版日
A12: 5 | C12: t_book_loans | G12: is_loaned | S12: status | W12: 貸出状況 | AE12: DB取得時に「貸出中」または「」にする
A13: 6 | C13: t_book_reviews | G13: avarage_review | S13: review | W13: 評価 | AE13: DB取得時に平均値にする

Sheet SQL仕様書
A1: ■画面設計書 | AG1: 文書番号 | AJ1: =表紙!AP1 -> BMS001
A2: 画面名 | C2: =表紙!G13 -> 書籍一覧 (一般) | Q2: 縦スクロール | T2: 可 | V2: 横スクロール | Y2: 可 | AA2: 画面タイプ | AD2: 通常 | AG2: 画面URL | AJ2: =変更履歴!AJ2 -> /book/list
A3: ■イベント定義 | AG3: ファイル名 | AJ3: =変更履歴!AJ3 -> book-list
A4: イベント
A6: SQL001 | C6: 初期表示
C8: SQL構文 | H8: カラム名 / テーブル名 / 条件 | W8: 備考
C9: SELECT | H9: id
H10: title
H11: author
H12: publication_ date
H13: CASE WHEN EXISTS ( SELECT 1 FROM t_book_loans WHERE m_book_lists.management_id = t_book_loans.management_id AND t_book_loans.return_date IS NULL ) THEN '貸出中' ELSE '' END AS is_loaned | W13: 書籍が貸出中かを取得して、文字列を取得する t_book_loans.return_dateがNULLの場合は、「貸出中」 t_book_loans.return_dateがNULL以外(貸出履歴なし または 日付がある)場合は「」
H14: ROUND(AVG(review), 1) AS avarage_review | W14: 評価の平均を取得する
C15: FROM | H15: m_book_lists
C16: LEFT JOIN | H16: t_book_reviews
C17: ON | H17: m_book_lists.isbn_code = t_book_reviews.isbn_code | W17: 同一書籍が別管理番号で複数ある場合もあるので、isbn_codeで結合する
C18: WHERE | H18: delete_flag = 0
C19: GROUP BY | H19: id, title, author, publication_ date, is_loaned
