Workbook

Sheet 表紙
AO1: 文書番号 | AP1: BMS001
G7: 社内システム構築
G9: 書籍管理システム
G11: 画面設計書
G13: 書籍詳細 (一般)
G16: ="最終更新日： "&IF(MAX(変更履歴!C5:C50)=0,"",TEXT(MAX(変更履歴!C5:C50),"YYYY/MM/DD")) -> 最終更新日： 2025/10/01
G18: マンパワーグループ株式会社

Sheet 変更履歴
A1: ■画面設計書 | AG1: 文書番号 | AJ1: =表紙!AP1 -> BMS001
A2: 画面名 | C2: =表紙!G13 -> 書籍詳細 (一般) | Q2: 縦スクロール | T2: 可 | V2: 横スクロール | Y2: 可 | AA2: 画面タイプ | AD2: 通常 | AG2: 画面URL | AJ2: /book/detail/{id}
A3: ■画面概要 | AG3: ファイル名 | AJ3: book-detail
A4: 版 | C4: 日付 | F4: 作成者 | J4: 変更箇所 | Q4: 修 正 内 容
A5: 0.01 | C5: 45931 | Q5: 新規作成

Sheet 画面概要
A1: ■画面設計書 | AG1: 文書番号 | AJ1: =表紙!AP1 -> BMS001
A2: 画面名 | C2: =表紙!G13 -> 書籍詳細 (一般) | Q2: 縦スクロール | T2: 可 | V2: 横スクロール | Y2: 可 | AA2: 画面タイプ | AD2: 通常 | AG2: 画面URL | AJ2: =変更履歴!AJ2 -> /book/detail/{id}
A3: ■画面概要 | AG3: ファイル名 | AJ3: =変更履歴!AJ3 -> book-detail
A4: 画面概要
A5: ・書籍の詳細を表示する
A6: ・書籍のを予約画面と貸出画面を開くことができる
A7: ・書籍が予約されている場合は、「一番近い日付」の「予約ユーザー」と「貸出予定日」を表示する
A8: ・書籍が貸出されている場合は、「貸出ユーザー」と「貸出日」を表示する
A9: ・予約ボタンは書籍が貸し出しされているときに表示される
A10: ・貸出ボタンは貸出可能なときのみ表示される
A11: ・同一書籍に対しては1人1予約までに制限、返却後に再度予約することは可能
A13: 機能
A14: ・書籍予約モーダル画面を開く
A15: ・書籍貸出モーダル画面を開く
A19: 前提条件
... A23: イベント一覧
A25: イベントID | C25: イベントトリガー | G25: 処理
A26: #001 | C26: ボタン押下 | G26: 書籍予約モーダル画面を開く
A27: #002 | C27: ボタン押下 | G27: 書籍貸出モーダル画面を開く
A31: 画面遷移先一覧
A32: ① | B32: /list
A33: ② | B33: /menu
A35: 外部参照
A36: 国立国会図書館サーチ 書影API
A37: fontawesome.com

Sheet 画面項目
A1: 画面項目 | AG1: 文書番号 | AJ1: =表紙!AP1 -> BMS001
A2: 画面名 | C2: =表紙!G13 -> 書籍詳細 (一般) | Q2: 縦スクロール | T2: 可 | V2: 横スクロール | Y2: 可 | AA2: 画面タイプ | AD2: 通常 | AG2: 画面URL | AJ2: =変更履歴!AJ2 -> /book/detail/{id}
A3: ■画面項目 | AG3: ファイル名 | AJ3: =変更履歴!AJ3 -> book-detail
A4: 画面イメージ
A31: 画面項目
A33: No. | C33: 項目ID | K33: 項目名(日本語) | R33: 部品種別 | V33: 必須 | X33: 初期値 | AB33: 桁数 | AD33: 備考 | AL33: イベントID
A34: 1 | C34: title_label | K34: 書籍名ラベル | R34: ラベル
A35: 2 | C35: title | K35: 書籍名 | R35: 表示項目
A36: 3 | C36: author_label | K36: 著者ラベル | R36: ラベル
A37: 4 | C37: author | K37: 著者 | R37: 表示項目
A38: 5 | C38: publisher_label | K38: 出版社ラベル | R38: ラベル
A39: 6 | C39: publisher | K39: 出版社 | R39: 表示項目
A40: 7 | C40: publicationDate_label | K40: 出版日ラベル | R40: ラベル
A41: 8 | C41: publicationDate | K41: 出版日 | R41: 表示項目
A42: 9 | C42: loanStatus_label | K42: 貸出状況ラベル | R42: ラベル
A43: 10 | C43: loanStatus | K43: 貸出状況 | R43: 表示項目
A44: 11 | C44: returnDueDate_label | K44: 返却予定日ラベル | R44: ラベル
A45: 12 | C45: returnDueDate | K45: 返却予定日 | R45: 表示項目
... A57: 24 | C57: alreadyReserved | K57: 予約フラグ | R57: 非表示項目
A58: 25 | C58: reserve_button | K58: 予約ボタン | R58: ボタン | AL58: #001
A59: 26 | C59: loan_button | K59: 貸出ボタン | R59: ボタン | AL59: #002
A60: 27 | C60: bookList_link | K60: 一覧リンク | R60: リンク

Sheet 画面遷移図
A1: ■画面設計書 | AG1: 文書番号 | AJ1: =表紙!AP1 -> BMS001
A2: 画面名 | C2: =表紙!G13 -> 書籍詳細 (一般) | Q2: 縦スクロール | T2: 可 | V2: 横スクロール | Y2: 可 | AA2: 画面タイプ | AD2: 通常 | AG2: 画面URL | AJ2: =変更履歴!AJ2 -> /book/detail/{id}
A3: ■画面遷移図 | AG3: ファイル名 | AJ3: =変更履歴!AJ3 -> book-detail
A4: 書籍一覧・予約画面遷移図

Sheet イベント定義
A1: ■画面設計書 | AG1: 文書番号 | AJ1: =表紙!AP1 -> BMS001
A2: 画面名 | C2: =表紙!G13 -> 書籍詳細 (一般) | Q2: 縦スクロール | T2: 可 | V2: 横スクロール | Y2: 可 | AA2: 画面タイプ | AD2: 通常 | AG2: 画面URL | AJ2: =変更履歴!AJ2 -> /book/detail/{id}
A3: ■イベント定義 | AG3: ファイル名 | AJ3: =変更履歴!AJ3 -> book-detail
A4: イベント
A6: #000 | C6: 初期表示
A8: 1 | C8: 画面に書籍情報を表示する
A10: 1-1 | D10: URLパラメーターより書籍のIDを取得する
A13: 1-2 | D13: データベースから書籍情報を取得する
E14: ① 「1-1」の書籍のIDを基にデータベースから書籍情報を取得する（※画面項目移動表No.2を参照）
E15: ② 貸出有無および予約有無に基づいて表示する文字列を変更する（下記の表を参照）
E17: 貸出・予約状況 | I17: 貸出・予約在りの条件 | N17: 貸出・予約在りの文字列 | U17: 貸出・予約なしの文字列
E18: 貸出状況 | I18: 「貸出日」がある | N18: 0000/00/00にxxに貸出済み | U18: 「貸出可」
E19: 予約状況 | I19: 「貸出予定日」がある | N19: 0000/00/00からxxに貸出予定 | U19: 「予約はありません」
E20: ※0000/00/00は「t_book_loansのloan_date」または「t_book_reservesのreserve_date」を参照して、日付を表示する
E21: ※xxは「t_book_loansのoid」または「t_book_reservesのoid」を参照して、ユーザー名を表示する
A24: 1-3 | D24: 取得した書籍情報を画面に描画する
E25: ① 「1-2」のデータを取得する
E26: ② 取得した書籍情報を画面に描画する（下記の表を参照）
E28: ヘッダー | I28: データ
E29: 書籍名 | I29: リーダブルコード
E30: 著者 | I30: Dustin Boswell
E31: 出版社 | I31: 技術評論社
E32: 出版日 | I32: 42450
E33: 貸出状況 | I33: 「貸出可」
E34: 返却予定日
E35: 予約状況 | I35: 0000/00/00からxxに貸出予定
E36: ISBNコード | I36: 978-4873115658
E37: 管理番号 | I37: book001
A40: 2 | C40: 画面の表紙を表示する
A42: 2-1 | D42: 「国立国会図書館サーチの書影API」から書籍の画像をJPG形式で取得する
E43: ① 「1-2」で取得したISBNコードを基にURLを作成する（「https://ndlsearch.ndl.go.jp/thumbnail/[isbnコード].jpg」の形式に作成する）
E44: ② 作成したURLを基に書影APIから書籍の画像を取得する
E46: ※詳細は下記URLを参照する
E47: 国立国会図書館サーチが提供する書影API | NDLサーチ | 国立国会図書館
A49: 2-2 | D49: 「2-1」で取得した画像を画面に描画する
E50: ① 画像を取得できた場合
F51: (1) 取得した画像を表示する
E53: ① 画像を取得できなかった場合
F54: (1) 「No Image」を表示する
A57: 3 | C57: 画面に評価とコメントを表示する
...

Sheet 画面項目移動表
A1: ■画面設計書 | AG1: 文書番号 | AJ1: =表紙!AP1 -> BMS001
A2: 画面名 | C2: =表紙!G13 -> 書籍詳細 (一般) | Q2: 縦スクロール | T2: 可 | V2: 横スクロール | Y2: 可 | AA2: 画面タイプ | AD2: 通常 | AG2: 画面URL | AJ2: =変更履歴!AJ2 -> /book/detail/{id}
A3: ■画面項目移動表 | AG3: ファイル名 | AJ3: =変更履歴!AJ3 -> book-detail
A4: 画面項目移動
A6: No.1 | C6: 検索 | E6: 初期表示データ | AA6: SQL001
A7: 番号 | C7: 取得元（サーバー） | G7: カラム名 | K7: 反映先１(バインド変数) | O7: カラム名 | AA7: 備考
A8: 1 | C8: セッション | G8: oid | K8: {1} | O8: oid | AA8: ログインユーザーのoidを取得する
A9: 2 | C9: URLパラメーター | G9: managment_id | K9: {2} | O9: managment_id | AA9: 表示しているページのURLパラメーターから管理番号を取得する
A12: No.2 | C12: 取得 | E12: 初期表示データ | AA12: SQL001
A13: 番号 | C13: 取得元（テーブル名） | G13: カラム名 | K13: 反映先１（DTO名） | O13: 変数名 | S13: 反映先２（画面項目ID） | W13: 画面項目名 | AA13: 備考
A14: 1 | C14: m_book_lists | G14: managment_id | K14: BookDetailDto | O14: managementId | S14: managementId | W14: 管理番号
A15: 2 | C15: m_book_lists | G15: title | K15: BookDetailDto | O15: title | S15: title | W15: 書籍名
A16: 3 | C16: m_book_lists | G16: author | K16: BookDetailDto | O16: author | S16: author | W16: 著者
A17: 4 | C17: m_book_lists | G17: publisher | K17: BookDetailDto | O17: publisher | S17: publisher | W17: 出版社
A18: 5 | C18: m_book_lists | G18: publication_ date | K18: BookDetailDto | O18: publicationDate | S18: publicationDate | W18: 出版日
A19: 6 | C19: m_book_lists | G19: isbn_code | K19: BookDetailDto | O19: isbnCode | S19: isbnCode | W19: ISBNコード | AA19: 「書影API」から書籍画像を取得するのにも使う
A20: 7 | C20: t_book_loans | G20: return_due_date | K20: BookDetailDto | O20: returnDueDate | S20: returnDueDate | W20: 返却予定日
A21: 8 | C21: t_book_loans | G21: returun_date | K21: BookDetailDto | O21: loans | S21: loans | W21: 貸出フラグ | AA21: 貸出ボタン制御のための値
A22: 9 | C22: t_book_loans | G22: loan_date | K22: BookDetailDto | O22: loanStatus | S22: loanStatus | W22: 貸出状況 | AA22: 「（「loan_date」）に（「loan_user」）に貸出済み」に変換する
A23: 10 | C23: t_book_loans | G23: loan_user | K23: BookDetailDto
A24: 11 | C24: t_book_reserves | G24: managment_id | K24: BookDetailDto | O24: alreadyReserved | S24: alreadyReserved | W24: 予約フラグ | AA24: 自分自身が該当書籍を予約しているかを管理するフラグ ・予約ボタン制御のための値
A25: 12 | C25: m_book_lists | G25: managment_id
A26: 13 | C26: reserve_info | G26: reserves_date | K26: BookDetailDto | O26: reservationStatus | S26: reservationStatus | W26: 予約状況 | AA26: 「（「reserves_date」）から（「reserves_user」）に貸出予定」に変換する
A27: 14 | C27: reserve_info | G27: reserve_user | K27: BookDetailDto
A28: 15 | C28: avg_review | G28: avg_review | K28: BookDetailDto | O28: review | S28: review | W28: 評価割合 | AA28: 「星の数」を計算するのにも使う
A29: 16 | C29: t_book_reviews | G29: comment | K29: BookDetailDto | O29: comments | S29: comments | W29: コメント | AA29: 「1対多」のため、リストで受け取る

Sheet SQL仕様書
A1: ■画面設計書 | AG1: 文書番号 | AJ1: =表紙!AP1 -> BMS001
A2: 画面名 | C2: =表紙!G13 -> 書籍詳細 (一般) | Q2: 縦スクロール | T2: 可 | V2: 横スクロール | Y2: 可 | AA2: 画面タイプ | AD2: 通常 | AG2: 画面URL | AJ2: =変更履歴!AJ2 -> /book/detail/{id}
A3: ■イベント定義 | AG3: ファイル名 | AJ3: =変更履歴!AJ3 -> book-detail
A4: イベント
A6: SQL001 | C6: 初期表示
C8: SQL構文 | H8: カラム名 / テーブル名 / 条件 | W8: 備考
C9: SELECT | H9: m_book_lists.management_id
C10: , | H10: m_book_lists.title
C11: , | H11: m_book_lists.author
C12: , | H12: m_book_lists.publisher
C13: , | H13: m_book_lists.publication_date
C14: , | H14: m_book_lists.isbn_code
C15: , | H15: t_book_loans.return_due_date
C16: , | H16: t_book_loans.loan_date
C17: , | H17: loan_users.name AS loan_user
C18: , | H18: EXISTS ( SELECT 1 FROM t_book_reserves WHERE oid = {1} AND t_book_reserves.loan_complete_flag = '1' ) AS reserve_flag | W18: 今現在、自分自身が該当書籍を予約しているかを取得する {1}はログインユーザーのoid
C19: , | H19: t_book_reserves_limit.reserves_date
C20: , | H20: reserves_users.name AS reserves_user
C21: , | H21: ROUND(AVG(review), 1) AS avarage_review | W21: 評価の平均を取得する
C22: , | H22: t_book_reviews.comment
C23: FROM | H23: m_book_lists
C24: LEFT JOIN | H24: t_book_loans
C25: ON | H25: m_book_lists.management_id= t_book_loans.management_id
C26: AND | H26: t_book_loans.return_date IS NULL | W26: 貸出されている書籍の場合は情報を取得する
C27: LEFT JOIN | H27: m_users AS loan_users | W27: 「予約テーブルとJOINしたユーザーテーブル」と区別するためにエイリアス名を付ける
C28: ON | H28: loan_user.oid= t_book_loans.oid
C29: LEFT JOIN | H29: ( SELECT management_id, oid, reserves_date FROM t_book_reserves WHERE t_book_reserves.loan_complete_flag = '1' ORDER BY reserves_date LIMIT 1 ) AS t_book_reserves_limit | W29: 予約日が最も近い書籍の情報１件を取得する
C30: ON | H30: m_book_lists.management_id= t_book_reserves_limit.management_id
C31: LEFT JOIN | H31: m_users AS reserves_users | W31: 「貸出テーブルとJOINしたユーザーテーブル」と区別するためにエイリアス名を付ける
C32: ON | H32: loan_user.oid= t_book_reserves_limit.oid
C33: LEFT JOIN | H33: t_book_reviews
C34: ON | H34: m_book_lists.isbn_code = t_book_reviews.isbn_code | W34: 同一書籍が別管理番号で複数ある場合もあるので、isbn_codeで結合する
C35: WHERE | H35: m_book_lists.delete_flag = 0
C36: AND | H36: m_book_lists.management_id = {2} | W36: 画面に表示している書籍を取得する / {2}は画面に表示している書籍の管理番号
C37: GROUP BY | H37: m_book_lists.management_id, m_book_lists.title, m_book_lists.author, m_book_lists.publisher, m_book_lists.publication_date, m_book_lists.isbn_code, t_book_loans.return_due_date, t_book_loans.loan_date, loan_users.name, t_book_reserves_limit.reserves_date, reserves_users.name, t_book_reviews.comment

Sheet 詳細画面イベント
A1: イベントID | B1: 処理内容 | G1: 画面項目移動表
B2: 1.初期表示 | G2: No.1 取得元(関連付け)書籍詳細 | M2: 取得元 | T2: 反映先
B3: 1-1.URLパラメーターより本のIDを取得。 | H3: DB(テーブル名) | I3: カラム名 | J3: 備考(カラム名補足) | N3: エンティティ名 | P3: 項目名 | R3: 処理 | U3: DTO名 | W3: 項目名
B4: 1-2.本のIDより本の詳細を取得。※画面項目移動表No.1を参照 | G4: DB | H4: m_book_lists | I4: id | J4: id | M4: Entity | N4: BookListsEntity | O4: id | P4: id | R4: 参照 | T4: 画面 | U4: id | W4: id
B5: 1-3.画面表示するテキストを作成。 | G5: DB | H5: m_book_lists | I5: managment_id | J5: 管理番号 | M5: Entity | N5: BookListsEntity | O5: managment_id | P5: 管理番号 | R5: 参照 | T5: 画面 | U5: managmentId | W5: 管理番号
G6: DB | H6: m_book_lists | I6: isbn_code | J6: ISBNコード | M6: Entity | N6: BookListsEntity | O6: isbn_code | P6: ISBNコード | R6: 参照 | T6: 画面 | U6: isbnCode | W6: ISBNコード
B7: 貸出・予約状況 | C7: 貸出・予約在り | D7: 貸出・予約なし | G7: DB | H7: m_book_lists | I7: title | J7: 書籍名 | M7: Entity | N7: BookListsEntity | O7: title | P7: 書籍名 | R7: 参照 | T7: 画面 | U7: title | W7: 書籍名
B8: 貸出状況 | C8: 0000/00/00にxxに貸出済み | D8: 「貸出可」 | G8: DB | H8: m_book_lists | I8: author | J8: 著者 | M8: Entity | N8: BookListsEntity | O8: author | P8: 著者 | R8: 参照 | T8: 画面 | U8: author | W8: 著者
B9: 予約状況 | C9: 0000/00/00からxxに貸出予定 | D9: 「予約はありません」 | G9: DB | H9: m_book_lists | I9: publisher | J9: 出版社 | M9: Entity | N9: BookListsEntity | O9: publisher | P9: 出版社 | R9: 参照 | T9: 画面 | U9: publisher | W9: 出版社
B10: ※0000/00/00はt_book_loansのloan_dateを参照 | G10: DB | H10: m_book_lists | I10: publication_ date | J10: 出版日 | M10: Entity | N10: BookListsEntity | O10: publication_date | P10: 出版日 | R10: 参照 | T10: 画面 | U10: publicationDate | W10: 出版日
B11: ※xxはt_book_loansのoidを参照 | G11: DB | H11: t_book_loans | I11: return_date | J11: 貸出日 | M11: Entity | N11: BookLoanEntity | O11: return_date | P11: 貸出日 | R11: 参照 | T11: 画面 | U11: loanStatus | W11: 貸出日
G12: DB | H12: t_book_loans | I12: return_due_date | J12: 返却予定日 | M12: Entity | N12: BookLoanEntity | O12: return_due_date | P12: 返却予定日 | R12: 参照 | T12: 画面 | U12: returnDueDate | W12: 返却予定日
B13: 本の表紙 | G13: DB | H13: t_book_reserves | I13: 「t_book_reservesのreserve_date」 | J13: 貸出予定日(予約) | M13: Entity | N13: BookReserveEntity | O13: Loan_complete_flag | P13: 貸出予定日(予約) | R13: 参照 | T13: 画面 | U13: reservationStatus | W13: 貸出予定日(予約)
B14: ・ISBNコードと管理番号を紐づけて表示 | T14: 画面 | U14: loan | W14: 貸出(true/false)
B19: 評価・コメント ※画面項目移動表No.2を参照 | G19: No.2 取得元(関連付け)コメント | M19: 取得元 | T19: 反映先
B20: ・評価とコメントを表示 | H20: DB(テーブル名) | I20: カラム名 | J20: 備考(カラム名補足) | N20: エンティティ名 | P20: 項目名 | R20: 処理 | U20: DTO名 | W20: 項目名
G21: DB | H21: t_book_reviews | I21: review | J21: 評価 | M21: Entity | N21: review | P21: 評価 | R21: 参照 | T21: 画面 | U21: review | W21: 評価
B22: 予約ボタン・貸出ボタン | G22: DB | H22: t_book_reviews | I22: comments | J22: コメント | M22: Entity | N22: comment | P22: コメント | R22: 参照 | T22: 画面 | U22: comment | W22: コメント
B23: ・予約ボタンと貸出ボタンを表示 | G23: DB | H23: t_book_reviews | I23: isbn_code | J23: ISBNコード | M23: Entity | N23: isbnCode | P23: ISBNコード | R23: 参照 | T23: 画面 | U23: isbnCode | W23: ISBNコード
B24: ・貸出ボタンは常に表示するが、貸出できない場合はボタンを押せない状態にしておく | M24: DTO | R24: 参照 | T24: 画面
M25: DTO | R25: 参照 | T25: 画面
B26: 貸出できない場合 | M26: DTO | R26: 参照 | T26: 画面
B27: 表示している本の返却日がNULLの場合 | C27: 貸出不可
B28: 本の返却日がNULL以外の場合 | C28: 貸出可
B29: 本が過去誰も借りていない場合 | C29: 貸出可
A36: #001 | B36: 2.予約ボタン押下
B37: 2-1.ユーザーが「予約」ボタンを押下する
B39: 2-2. 予約画面（モーダルウィンドウ）を表示する
B40: ※1冊の本に対する予約情報（管理番号、貸出予定日、返却予定日）の情報を取得する
B41: ※ flatpickrで貸出予定日を実装予定
T42: 反映先
G43: 画面項目移動表 | L43: 取得元 | U43: DB(テーブル名) | W43: カラム名 | Y43: 備考(カラム名補足)
B44: ・予約可能日は返却予定日または返却日の次の日から | G44: 取得元(関連付け) | M44: エンティティ名 | O44: 項目名 | Q44: 処理 | T44: DB | U44: m_book_lists | W44: reserve_date | Y44: 貸出予定日(予約)
B45: 予約 | C45: 返却日 | D45: 予約可能日 | G45: 画面 | H45: フォーム名 | I45: 項目名 | L45: DTO | M45: managementId | O45: 管理番号 | Q45: 更新 | T45: DB | U45: t_book_reserves | W45: return_due_date | Y45: 返却予定日
B46: 予約が無い場合 | C46: NULLのとき（貸出中） | D46: 返却予定日の次の日 | G46: 画面 | H46: managementId | I46: 管理番号 | L46: DTO | M46: oid | O46: ユーザーID(OID ) | Q46: 更新 | T46: DB | U46: t_book_reserves | W46: reserve_date | Y46: 貸出予定日(予約)
C47: NULLじゃないとき | D47: 返却日の次の日 | G47: 画面 | H47: oid | I47: ユーザーID(OID ) | L47: DTO | M47: reservesDate | O47: 貸出予定日(予約) | Q47: 更新 | T47: DB | U47: t_book_reserves | W47: return_due_date | Y47: 返却予定日
B48: 予約がある場合 | C48: NULLのとき（貸出中） | D48: 返却予定日の次の日かつ予約かぶっていない日 | G48: 画面 | H48: reservesDate | I48: 貸出予定日 | L48: DTO | M48: returnDueDate | O48: 返却予定日 | Q48: 更新 | T48: DB
C49: NULLじゃないとき | D49: 返却日の次の日かつ予約かぶっていない日 | G49: 画面 | H49: returnDueDate | I49: 返却予定日 | L49: DTO | T49: DB
G50: 画面 | L50: DTO
B51: 2-3. ユーザーが貸出予定日を入力する | G51: 画面
...

Sheet 追加の詳細メモ
A1: 貸出 | E1: loan_complete_flag | I1: フラグ | J1: 意味
E2: 貸出前 | G2: 0 | I2: 0 | J2: 初期値：予約されているが貸出されていない
A3: 貸出期間は最大1か月まで | E3: 予約後に貸出した | G3: 1 | I3: 1 | J3: 貸出済み：予約期間内に貸出された
A4: 予約している日付は表示、他の人の予約日は非表示 | E4: 予約期間を過ぎたら | G4: 2 | I4: 2 | J4: 失効：予約期間を過ぎても貸出されなかった（＝0のまま期限切れ）
A5: 本人が予約期間内に貸出したら、t_book_reserveテーブルのloan_complete_flagを１に更新にする。 | J5: ２がバッチ処理対象 1は貸出処理のときにする
E6: 予約期間を過ぎる → 返却日を過ぎる
A7: (Java) 予約と貸出の紐付け 予約には「予約者ID」「予約期間（開始日〜終了日）」を持たせる。 | E7: バッチ処理で「予約期間を過ぎたか」を自動確認して削除 | J7: ０→１の処理 | L7: 予約期間と貸出期間が1日でも重なっていれば、予約に対して貸出が成立したとみなす
A8: 1.貸出時に「その本に予約があるか」をチェック。 | J8: ０→２の処理 | L8: 0時に今日の日付がretrunduedateより大きかったらフラグを更新
A9: 2.予約がある場合、「自分のID == 予約者ID」かどうかを確認。
A10: 3.本人予約なら貸出日OK かつ 色を黄色にする
A12: 貸出期間が予約期間をまたぐ／前倒し／後ろ倒し → OK（他の予約がなければ）
A14: 貸出📚
A15: 本の貸出可能日を取得する（Flatpickr用）
A16: GET [api/loan-info]
A17: 貸出を登録する＆予約していた場合は予約フラグの更新
A18: POST[api/loan-register]
A20: 🖥️ フロントエンド（FE）で実装すべきこと
A21: 1. 入力フォームの制御
A22: 貸出希望日・返却希望日の入力UI
A24: 最大1か月まで選択可能に制限（カレンダーUIなど）
... A39: 一致している場合は、loginuserReservedDatesに日付を入れる
A40: 渡される情報 | B40: フィールド名
A41: ほかのユーザーの予約日情報 | B41: otherReservedDates
A42: ログインユーザーの予約日情報 | B42: loginuserReservedDates
A45: 2. 貸出許可判定ロジック
A46: 本人予約かつ予約期間内であれば、loan_complete_flag = 1 に更新
A47: 予約期間内: 1日でも予約期間と被る
A48: 予約期間をまたぐ／前倒し／後ろ倒し → OK（他の予約がなければ）
A50: ３. DB更新処理
A51: 貸出が許可された場合、貸出情報をDBに登録
A52: loan_complete_flag を更新

Sheet SQL課題
A1: 貸出テーブル | F1: 書籍マスタ | M1: 1 | N1: FROM
A2: 本ID | B2: ユーザーID | C2: 日付 | D2: 返却日 | F2: 本ID | O2: 最初にメインのテーブルが選ばれます。
A3: 1 | B3: 1 | D3: あり | F3: 1 | M3: 2 | N3: JOIN / LEFT JOIN / INNER JOIN など
A4: 1 | B4: 2 | D4: あり | O4: 結合条件に従って、他のテーブルと結合されます。
A5: 1 | B5: 3 | D5: なし | M5: 3 | N5: ON
A6: 2 | B6: 4 | D6: なし | O6: 結合条件が適用され、結合対象の行がフィルタされます。
M7: 4 | N7: WHERE
A8: 予約テーブル | F8: ユーザーマスタ | O8: 結合後のデータに対して、行レベルのフィルタがかかります。
A9: 本ID | B9: ユーザーID | C9: 日付 | D9: フラグ | F9: ユーザーID | G9: ユーザー名 | M9: 5 | N9: GROUP BY
A10: 1 | B10: 1 | D10: 期間外 | F10: 1 | G10: A | O10: WHEREで絞り込まれたデータをグループ化します。
A11: 1 | B11: 2 | D11: 期間内 | F11: 2 | G11: B | M11: 6 | N11: HAVING（もしあれば）
A12: 1 | B12: 4 | D12: 期間内 | F12: 3 | G12: C | O12: グループ化されたデータに対して、グループ単位でフィルタします。
F13: 4 | G13: D | M13: 7 | N13: SELECT
O14: 必要な列や集計関数を選択します。
M15: 8 | N15: DISTINCT（もしあれば）
A16: (1) 予約テーブルと貸出テーブルのユーザー情報が被る | G16: JOINでテーブルに名前をつける | O16: 重複行を除外します。
A17: 本ID | B17: ユーザーID | C17: ユーザー名 | D17: ユーザーID | E17: ユーザー名 | G17: LEFT JOIN m_users AS reserve_user | M17: 9 | N17: ORDER BY（もしあれば）
A18: 1 | B18: 3 | C18: C | D18: 2 | E18: B | O18: 結果を並び替えます。
M19: 10 | N19: LIMIT / OFFSET（もしあれば）
A22: (2) 予約日が最も近い書籍の情報１件を取得する | M22: 表示する行数を制限します。
A23: 本ID | B23: ユーザーID | G23: ORDER BY reserves_date ASC
A24: 1 | B24: 2 | G24: LIMIT 1
A25: 1 | B25: 4 | C25: ← 取得したくない！ | G25: で1件だけ取得
A29: (3) 貸出されていない書籍が条件で全情報が消える
A30: 本ID | B30: 書籍名 | C30: ユーザーID | D30: 日付 | E30: 返却日 | G30: AND l.return_date IS NULL
A31: 1 | B31: あ | C31: 1 | E31: あり | G31: でJOINのときに条件を付ける
A32: 1 | B32: あ | C32: 2 | E32: あり
A33: 1 | B33: あ | C33: 3 | E33: なし
A35: JOIN条件
A36: 本ID
A37: WHERE条件
A38: 返却されていない
A40: 本ID | B40: 書籍名 | C40: ユーザーID | D40: 日付 | E40: 返却日
A41: 1 | B41: あ | C41: 3 | E41: なし
A43: 貸出情報を付け足している
A45: 本ID | B45: 書籍名 | C45: ユーザーID | D45: 日付 | E45: 返却日
A46: 1 | B46: あ | C46: 1 | E46: あり
A47: 1 | B47: あ | C47: 2 | E47: あり
A48: 1 | B48: あ | C48: 3 | E48: あり
A50: JOIN条件
...

Sheet トランザクションメモ
B1: 1人目 | D1: ２人目 | H1: 1人目 | J1: ２人目
A2: 1 | B2: 画面 | G2: 1 | H2: 画面
C3: 2 | D3: 画面 | I3: 2 | J3: 画面
A4: 3 | B4: 予約ボタン押下
G5: 3 | H5: 予約ボタン押下 | I5: 4 | J5: 予約ボタン押下
A6: 4 | B6: 予約完了
C7: 5 | D7: 予約ボタン押下 | G7: 5 | H7: ロック
I8: 6 | J8: ロック中のため操作不可
C9: 6 | D9: 予約不可 | G9: 7 | H9: 予約完了(commit)
I10: 8 | J10: 予約不可
B12: 1人目 | D12: ２人目
A13: 1 | B13: 貸出画面
C14: 2 | D14: 予約画面
A15: 3 | B15: 貸出ボタン押下
A17: 4 | B17: 貸出完了
C18: 5 | D18: 予約ボタン押下
C20: 6 | D20: 予約不可
B22: Aさん | D22: Bさん
B23: Bさんに1000円送金
B25: -1000円完了 | D25: Aさんから1000円受け取り
D27: +1000円 エラー
